Workbook

Sheet DeparaIMG
A1: Tipo | B1: Promax | C1: EG | D1: SKU | E1: Nome IMG | F1: Caminho
A2: CERV | B2: 9224 | C2: 92247 | D2: AP 269 | E2: =SUBSTITUTE(D2," ","") -> AP269 | F2: =E2&".png" -> AP269.png
A3: CERV | B3: 18858 | C3: 188581 | D3: AP 269 MP | E3: =SUBSTITUTE(D3," ","") -> AP269MP | F3: =E3&".png" -> AP269MP.png
A4: CERV | B4: 9067 | C4: 90670 | D4: AP 350 | E4: =SUBSTITUTE(D4," ","") -> AP350 | F4: =E4&".png" -> AP350.png
A5: NAB | B5: 2357 | C5: 23572 | D5: BARE P2 | E5: BAREP2 | F5: =E5&".png" -> BAREP2.png
A6: CERV | B6: 12948 | C6: 129486 | D6: BC 0 350 | E6: =SUBSTITUTE(D6," ","") -> BC0350 | F6: =E6&".png" -> BC0350.png
A7: CERV | B7: 1898 | C7: 18986 | D7: BC 269 | E7: =SUBSTITUTE(D7," ","") -> BC269 | F7: =E7&".png" -> BC269.png
A8: CERV | B8: 18860 | C8: 188607 | D8: BC 269 MP | E8: =SUBSTITUTE(D8," ","") -> BC269MP | F8: =E8&".png" -> BC269MP.png
A9: CERV | B9: 9069 | C9: 90696 | D9: BC 350 | E9: =SUBSTITUTE(D9," ","") -> BC350 | F9: =E9&".png" -> BC350.png
A10: MATCH | B10: - | C10: - | D10: BEATS LN | E10: =SUBSTITUTE(D10," ","") -> BEATSLN | F10: =E10&".png" -> BEATSLN.png
A11: MATCH | B11: - | C11: - | D11: BEATS LT | E11: =SUBSTITUTE(D11," ","") -> BEATSLT | F11: =E11&".png" -> BEATSLT.png
A12: CERV | B12: 31064 | C12: 310649 | D12: BUD 269 | E12: =SUBSTITUTE(D12," ","") -> BUD269 | F12: =E12&".png" -> BUD269.png
A13: CERV | B13: 34137 | C13: 341370 | D13: BUD 269 MP | E13: =SUBSTITUTE(D13," ","") -> BUD269MP | F13: =E13&".png" -> BUD269MP.png
A14: CERV | B14: 21020 | C14: 210203 | D14: BUD 350 | E14: =SUBSTITUTE(D14," ","") -> BUD350 | F14: =E14&".png" -> BUD350.png
A15: CERV | B15: 17808 | C15: 178087 | D15: BUD LN | E15: =SUBSTITUTE(D15," ","") -> BUDLN | F15: =E15&".png" -> BUDLN.png
A16: CERV | B16: 22177 | C16: 221770 | D16: BUD 0 350 | E16: BUDZERO350 | F16: =E16&".png" -> BUDZERO350.png
A17: CERV | B17: 22180 | C17: 221804 | D17: BUD 0 LN | E17: BUDZEROLN | F17: =E17&".png" -> BUDZEROLN.png
A18: CERV | B18: 32392 | C18: 323923 | D18: COR 269 | E18: =SUBSTITUTE(D18," ","") -> COR269 | F18: =E18&".png" -> COR269.png
A19: CERV | B19: 20651 | C19: 206516 | D19: COR 350 | E19: =SUBSTITUTE(D19," ","") -> COR350 | F19: =E19&".png" -> COR350.png
A20: CERV | B20: 34263 | C20: 342634 | D20: COR 0 350 | E20: CORCERO350 | F20: =E20&".png" -> CORCERO350.png
A21: CERV | B21: 27866 | C21: 278663 | D21: COR 0 LN | E21: CORCEROLN | F21: =E21&".png" -> CORCEROLN.png
A22: CERV | B22: 18836 | C22: 188367 | D22: COR LN | E22: =SUBSTITUTE(D22," ","") -> CORLN | F22: =E22&".png" -> CORLN.png
A23: MATCH | B23: 35319 | C23: 353193 | D23: FF 350 | E23: =SUBSTITUTE(D23," ","") -> FF350 | F23: =E23&".png" -> FF350.png
A24: MATCH | B24: 35113 | C24: 351130 | D24: FF LN | E24: =SUBSTITUTE(D24," ","") -> FFLN | F24: =E24&".png" -> FFLN.png
A25: NAB | B25: 12360 | C25: 123604 | D25: GCA LT269 | E25: GCA269 | F25: =E25&".png" -> GCA269.png
A26: NAB | B26: 9084 | C26: 90845 | D26: GCA LT350 | E26: GCA350 | F26: =E26&".png" -> GCA350.png
A27: NAB | B27: 8411 | C27: 84111 | D27: GCA P1,5 | E27: GCAP1,5 | F27: =E27&".png" -> GCAP1,5.png
A28: NAB | B28: 2132 | C28: 21329 | D28: GCA P1 | E28: GCAP1 | F28: =E28&".png" -> GCAP1.png
A29: NAB | B29: 2349 | C29: 23499 | D29: GCA P2 | E29: GCAP2 | F29: =E29&".png" -> GCAP2.png
A30: NAB | B30: 8793 | C30: 87932 | D30: H2OH P1,5 | E30: H2OHP1,5 | F30: =E30&".png" -> H2OHP1,5.png
A31: NAB | B31: 8791 | C31: 87916 | D31: H2OH P500 | E31: H2OHP500 | F31: =E31&".png" -> H2OHP500.png
A32: CERV | B32: 24346 | C32: 243469 | D32: MIC 269 | E32: =SUBSTITUTE(D32," ","") -> MIC269 | F32: =E32&".png" -> MIC269.png
A33: CERV | B33: 4262 | C33: 42622 | D33: MIC 350 | E33: =SUBSTITUTE(D33," ","") -> MIC350 | F33: =E33&".png" -> MIC350.png
A34: CERV | B34: 24168 | C34: 241687 | D34: MIC LN | E34: =SUBSTITUTE(D34," ","") -> MICLN | F34: =E34&".png" -> MICLN.png
A35: CERV | B35: 21946 | C35: 219469 | D35: ORI 269 | E35: =SUBSTITUTE(D35," ","") -> ORI269 | F35: =E35&".png" -> ORI269.png
A36: CERV | B36: 33324 | C36: 333245 | D36: ORI 269 MP | E36: =SUBSTITUTE(D36," ","") -> ORI269MP | F36: =E36&".png" -> ORI269MP.png
A37: NAB | B37: 14842 | C37: 148429 | D37: PC LT269 | E37: PC269 | F37: =E37&".png" -> PC269.png
A38: NAB | B38: 9274 | C38: 92742 | D38: PCB LT350 | E38: PCB350 | F38: =E38&".png" -> PCB350.png
A39: NAB | B39: 504 | C39: 5041 | D39: PC P2 | E39: PCP2 | F39: =E39&".png" -> PCP2.png
A40: CERV | B40: 1745 | C40: 17459 | D40: SK 269 | E40: =SUBSTITUTE(D40," ","") -> SK269 | F40: =E40&".png" -> SK269.png
...

Sheet CALENDARIO
A1: SKU | B1: Data | C1: Tipo
A2: NAB | B2: 46174 | C2: 1ª QUINZ
A3: NAB | B3: 46175 | C3: 1ª QUINZ
A4: NAB | B4: 46176 | C4: 1ª QUINZ
A5: NAB | B5: 46177 | C5: 1ª QUINZ
A6: NAB | B6: 46178 | C6: 1ª QUINZ
A7: NAB | B7: 46179 | C7: 1ª QUINZ
A8: NAB | B8: 46180 | C8: 1ª QUINZ
A9: NAB | B9: 46181 | C9: 1ª QUINZ
A10: NAB | B10: 46182 | C10: 1ª QUINZ
A11: NAB | B11: 46183 | C11: 1ª QUINZ
A12: NAB | B12: 46184 | C12: 1ª QUINZ
A13: NAB | B13: 46185 | C13: 1ª QUINZ
... A498: CERV | B498: 46327 | C498: 1ª QUINZ
A499: CERV | B499: =B498+1 -> 46328 | C499: 1ª QUINZ
A500: CERV | B500: =B499+1 -> 46329 | C500: 1ª QUINZ
A501: CERV | B501: =B500+1 -> 46330 | C501: 1ª QUINZ
A502: CERV | B502: =B501+1 -> 46331 | C502: 1ª QUINZ
A503: CERV | B503: =B502+1 -> 46332 | C503: 1ª QUINZ
A504: CERV | B504: =B503+1 -> 46333 | C504: 1ª QUINZ
A505: CERV | B505: =B504+1 -> 46334 | C505: 1ª QUINZ
A506: CERV | B506: =B505+1 -> 46335 | C506: 1ª QUINZ
A507: CERV | B507: =B506+1 -> 46336 | C507: 1ª QUINZ
A508: CERV | B508: =B507+1 -> 46337 | C508: 1ª QUINZ
A509: CERV | B509: =B508+1 -> 46338 | C509: 1ª QUINZ
A510: CERV | B510: =B509+1 -> 46339 | C510: 1ª QUINZ
... A526: CERV | B526: =B525+1 -> 46355 | C526: 2ª QUINZ
A527: NAB | B527: 46327 | C527: 1ª QUINZ
A528: NAB | B528: =B527+1 -> 46328 | C528: 1ª QUINZ
A529: NAB | B529: =B528+1 -> 46329 | C529: 1ª QUINZ
A530: NAB | B530: =B529+1 -> 46330 | C530: 1ª QUINZ
A531: NAB | B531: =B530+1 -> 46331 | C531: 1ª QUINZ
A532: NAB | B532: =B531+1 -> 46332 | C532: 1ª QUINZ
A533: NAB | B533: =B532+1 -> 46333 | C533: 1ª QUINZ
A534: NAB | B534: =B533+1 -> 46334 | C534: 1ª QUINZ
A535: NAB | B535: 46338 | C535: 2ª QUINZ
A536: NAB | B536: =B535+1 -> 46339 | C536: 2ª QUINZ
A537: NAB | B537: =B536+1 -> 46340 | C537: 2ª QUINZ
A538: NAB | B538: =B537+1 -> 46341 | C538: 2ª QUINZ
A539: NAB | B539: =B538+1 -> 46342 | C539: 2ª QUINZ
...

Sheet MECANICA
A1: Mes | B1: SKU | C1: Tipo | D1: Texto
A2: Setembro | B2: NAB | C2: Sell in | D2: Ativação: Quinzenal
A3: Setembro | B3: NAB | C3: Sell in | D3: Negociação: Sell In e Sell Out
A4: Setembro | B4: NAB | C4: Sell in | D4: Apuração Varejo: Pagamento 60% do Sell In no Mês
A5: Setembro | B5: NAB | C5: Sell in | D5: Apuração Cash: Pagamento 100% do Sell In no Mês
A6: Setembro | B6: NAB | C6: Sell out | D6: Ativação: Quinzenal
A7: Setembro | B7: NAB | C7: Sell out | D7: Negociação: Sell In e Sell Out
A8: Setembro | B8: NAB | C8: Sell out | D8: Apuração Varejo: 100% no período, com check de TTC
A9: Setembro | B9: CERV | C9: Sell in | D9: Negociação: Sell In e Sell Out
A10: Setembro | B10: CERV | C10: Sell in | D10: HE/CP/MATCH: 50% Volume Mês
A11: Setembro | B11: CERV | C11: Sell in | D11: Core Varejo: 50% Volume do Mês
A12: Setembro | B12: CERV | C12: Sell in | D12: Core Cash: 60 R$/hl
... A72: Novembro | B72: MERCAPROMO | C72: MERCAPROMO | D72: MATCH: Máximo 4 combos por CPF

Sheet PRODUTOS
A1: Mes | B1: Tipo | C1: Regional | D1: Canal | E1: Quinzena | F1: SKU | G1: De | H1: Para | I1: Imagem
A2: Setembro | B2: NAB | C2: AM | D2: ATACADO | E2: 1 | F2: GCA P1 | G2: 4.99 | H2: 4.69 | I2: =_xlfn.XLOOKUP(F2,DeparaIMG!D:D,DeparaIMG!F:F,,0) -> GCAP1.png
A3: Setembro | B3: NAB | C3: RR/AC | D3: ATACADO | E3: 1 | F3: GCA P1,5 | G3: 6.49 | H3: 6.19 | I3: =_xlfn.XLOOKUP(F3,DeparaIMG!D:D,DeparaIMG!F:F,,0) -> GCAP1,5.png
A4: Setembro | B4: NAB | C4: DF | D4: ATACADO | E4: 1 | F4: GCA P1,5 | G4: 6.49 | H4: 6.19 | I4: =_xlfn.XLOOKUP(F4,DeparaIMG!D:D,DeparaIMG!F:F,,0) -> GCAP1,5.png
A5: Setembro | B5: NAB | C5: GO | D5: ATACADO | E5: 1 | F5: GCA P1,5 | G5: 6.49 | H5: 6.19 | I5: =_xlfn.XLOOKUP(F5,DeparaIMG!D:D,DeparaIMG!F:F,,0) -> GCAP1,5.png
A6: Setembro | B6: NAB | C6: TO/MT/MS | D6: ATACADO | E6: 1 | F6: GCA P1,5 | G6: 6.49 | H6: 6.19 | I6: =_xlfn.XLOOKUP(F6,DeparaIMG!D:D,DeparaIMG!F:F,,0) -> GCAP1,5.png
A7: Setembro | B7: NAB | C7: AM | D7: ATACADO | E7: 1 | F7: PC P2 | G7: 7.79 | H7: 7.29 | I7: =_xlfn.XLOOKUP(F7,DeparaIMG!D:D,DeparaIMG!F:F,,0) -> PCP2.png
A8: Setembro | B8: NAB | C8: RR/AC | D8: ATACADO | E8: 1 | F8: PC P2 | G8: 8.49 | H8: 7.99 | I8: =_xlfn.XLOOKUP(F8,DeparaIMG!D:D,DeparaIMG!F:F,,0) -> PCP2.png
A9: Setembro | B9: NAB | C9: DF | D9: ATACADO | E9: 1 | F9: PC P2 | G9: 7.49 | H9: 6.99 | I9: =_xlfn.XLOOKUP(F9,DeparaIMG!D:D,DeparaIMG!F:F,,0) -> PCP2.png
A10: Setembro | B10: NAB | C10: GO | D10: ATACADO | E10: 1 | F10: PC P2 | G10: 7.49 | H10: 6.99 | I10: =_xlfn.XLOOKUP(F10,DeparaIMG!D:D,DeparaIMG!F:F,,0) -> PCP2.png
A11: Setembro | B11: NAB | C11: TO/MT/MS | D11: ATACADO | E11: 1 | F11: PC P2 | G11: 8.49 | H11: 7.99 | I11: =_xlfn.XLOOKUP(F11,DeparaIMG!D:D,DeparaIMG!F:F,,0) -> PCP2.png
A12: Setembro | B12: NAB | C12: AM | D12: ATACADO | E12: 1 | F12: BARE P2 | G12: 5.49 | H12: 5.19 | I12: =_xlfn.XLOOKUP(F12,DeparaIMG!D:D,DeparaIMG!F:F,,0) -> BAREP2.png
A13: Setembro | B13: NAB | C13: RR/AC | D13: ATACADO | E13: 1 | F13: H2OH P500 | G13: 5.29 | H13: 4.99 | I13: =_xlfn.XLOOKUP(F13,DeparaIMG!D:D,DeparaIMG!F:F,,0) -> H2OHP500.png
... A1220: Outubro | B1220: CERV | C1220: RO | D1220: VAREJO | E1220: 2 | F1220: ORI 269 MP | G1220: 3.69 | H1220: 3.39 | I1220: =_xlfn.XLOOKUP(F1220,DeparaIMG!D:D,DeparaIMG!F:F,,0) -> ORI269MP.png
A1221: Outubro | B1221: MERCAPROMO | C1221: DF | D1221: MERCAPROMO | E1221: 1 | F1221: AP 269 | G1221: Leve:15 | H1221: Pague:12 | I1221: =_xlfn.XLOOKUP(F1221,DeparaIMG!D:D,DeparaIMG!F:F,,0) -> AP269.png
A1222: Outubro | B1222: MERCAPROMO | C1222: GO | D1222: MERCAPROMO | E1222: 1 | F1222: AP 269 | G1222: Leve:15 | H1222: Pague:12 | I1222: =_xlfn.XLOOKUP(F1222,DeparaIMG!D:D,DeparaIMG!F:F,,0) -> AP269.png
A1223: Outubro | B1223: MERCAPROMO | C1223: MT | D1223: MERCAPROMO | E1223: 2 | F1223: AP 269 | G1223: Leve:15 | H1223: Pague:12 | I1223: =_xlfn.XLOOKUP(F1223,DeparaIMG!D:D,DeparaIMG!F:F,,0) -> AP269.png
A1224: Outubro | B1224: MERCAPROMO | C1224: FORT DF/GO | D1224: ATACADO | E1224: 1 | F1224: AP 269 | G1224: Leve:15 | H1224: Pague:12 | I1224: =_xlfn.XLOOKUP(F1224,DeparaIMG!D:D,DeparaIMG!F:F,,0) -> AP269.png
A1225: Outubro | B1225: MERCAPROMO | C1225: MS | D1225: MERCAPROMO | E1225: 1 | F1225: SK 269 | G1225: Leve:15 | H1225: Pague:12 | I1225: =_xlfn.XLOOKUP(F1225,DeparaIMG!D:D,DeparaIMG!F:F,,0) -> SK269.png
A1226: Outubro | B1226: MERCAPROMO | C1226: MT | D1226: MERCAPROMO | E1226: 1 | F1226: SK 269 | G1226: Leve:15 | H1226: Pague:12 | I1226: =_xlfn.XLOOKUP(F1226,DeparaIMG!D:D,DeparaIMG!F:F,,0) -> SK269.png
A1227: Outubro | B1227: MERCAPROMO | C1227: FORT MT/MS | D1227: ATACADO | E1227: 1 | F1227: SK 269 | G1227: Leve:15 | H1227: Pague:12 | I1227: =_xlfn.XLOOKUP(F1227,DeparaIMG!D:D,DeparaIMG!F:F,,0) -> SK269.png
A1228: Outubro | B1228: MERCAPROMO | C1228: DF | D1228: MERCAPROMO | E1228: 2 | F1228: BC 269 | G1228: Leve:15 | H1228: Pague:12 | I1228: =_xlfn.XLOOKUP(F1228,DeparaIMG!D:D,DeparaIMG!F:F,,0) -> BC269.png
A1229: Outubro | B1229: MERCAPROMO | C1229: GO | D1229: MERCAPROMO | E1229: 2 | F1229: BC 269 | G1229: Leve:15 | H1229: Pague:12 | I1229: =_xlfn.XLOOKUP(F1229,DeparaIMG!D:D,DeparaIMG!F:F,,0) -> BC269.png
A1230: Outubro | B1230: MERCAPROMO | C1230: MS | D1230: MERCAPROMO | E1230: 2 | F1230: BC 269 | G1230: Leve:15 | H1230: Pague:12 | I1230: =_xlfn.XLOOKUP(F1230,DeparaIMG!D:D,DeparaIMG!F:F,,0) -> BC269.png
A1231: Outubro | B1231: MERCAPROMO | C1231: MT | D1231: MERCAPROMO | E1231: 2 | F1231: BC 269 | G1231: Leve:15 | H1231: Pague:12 | I1231: =_xlfn.XLOOKUP(F1231,DeparaIMG!D:D,DeparaIMG!F:F,,0) -> BC269.png
A1232: Outubro | B1232: MERCAPROMO | C1232: FORT DF/GO | D1232: ATACADO | E1232: 2 | F1232: BC 269 | G1232: Leve:15 | H1232: Pague:12 | I1232: =_xlfn.XLOOKUP(F1232,DeparaIMG!D:D,DeparaIMG!F:F,,0) -> BC269.png
... A1337: Outubro | B1337: MERCAPROMO | C1337: FORT MT/MS | D1337: ATACADO | E1337: 2 | F1337: BEATS - FF | G1337: Leve 2 Beats | H1337: Ganhe 1 FF | I1337: =_xlfn.XLOOKUP(F1337,DeparaIMG!D:D,DeparaIMG!F:F,,0) -> BEATSFF.png
A1338: Outubro | B1338: CERV | C1338: AM/PA/RR | D1338: ATACADO | E1338: POWER PACKS | F1338: SK 269 | G1338: 3.29 | H1338: 2.99 | I1338: =_xlfn.XLOOKUP(F1338,DeparaIMG!D:D,DeparaIMG!F:F,,0) -> SK269.png
A1339: Outubro | B1339: CERV | C1339: AM/PA/RR | D1339: ATACADO | E1339: POWER PACKS | F1339: BDM 269 | G1339: 3.39 | H1339: 2.49 | I1339: =_xlfn.XLOOKUP(F1339,DeparaIMG!D:D,DeparaIMG!F:F,,0) -> BDM269.png
A1340: Outubro | B1340: CERV | C1340: AM/PA/RR | D1340: ATACADO | E1340: POWER PACKS | F1340: SPT 269 | G1340: 3.99 | H1340: 3.49 | I1340: =_xlfn.XLOOKUP(F1340,DeparaIMG!D:D,DeparaIMG!F:F,,0) -> SPT269.png
A1341: Outubro | B1341: CERV | C1341: AM/PA/RR | D1341: ATACADO | E1341: POWER PACKS | F1341: STE 269 | G1341: 4.29 | H1341: 3.49 | I1341: =_xlfn.XLOOKUP(F1341,DeparaIMG!D:D,DeparaIMG!F:F,,0) -> STE269.png
A1342: Outubro | B1342: CERV | C1342: AM/PA/RR | D1342: ATACADO | E1342: POWER PACKS | F1342: COR 269 | G1342: 4.69 | H1342: 3.99 | I1342: =_xlfn.XLOOKUP(F1342,DeparaIMG!D:D,DeparaIMG!F:F,,0) -> COR269.png
A1343: Outubro | B1343: CERV | C1343: AM/PA/RR | D1343: ATACADO | E1343: POWER PACKS | F1343: BC 350 | G1343: 3.79 | H1343: 3.39 | I1343: =_xlfn.XLOOKUP(F1343,DeparaIMG!D:D,DeparaIMG!F:F,,0) -> BC350.png
A1344: Outubro | B1344: CERV | C1344: AM/PA/RR | D1344: ATACADO | E1344: POWER PACKS | F1344: SPT LN | G1344: 6.49 | H1344: 5.99 | I1344: =_xlfn.XLOOKUP(F1344,DeparaIMG!D:D,DeparaIMG!F:F,,0) -> SPTLN.png
A1345: Outubro | B1345: CERV | C1345: MT | D1345: ATACADO | E1345: POWER PACKS | F1345: SK 269 | G1345: 3.29 | H1345: 3.09 | I1345: =_xlfn.XLOOKUP(F1345,DeparaIMG!D:D,DeparaIMG!F:F,,0) -> SK269.png
A1346: Outubro | B1346: CERV | C1346: MT | D1346: ATACADO | E1346: POWER PACKS | F1346: BUD 269 | G1346: 3.49 | H1346: 2.99 | I1346: =_xlfn.XLOOKUP(F1346,DeparaIMG!D:D,DeparaIMG!F:F,,0) -> BUD269.png
A1347: Outubro | B1347: CERV | C1347: MT | D1347: ATACADO | E1347: POWER PACKS | F1347: BDM 269 | G1347: 3.59 | H1347: 3.09 | I1347: =_xlfn.XLOOKUP(F1347,DeparaIMG!D:D,DeparaIMG!F:F,,0) -> BDM269.png
A1348: Outubro | B1348: CERV | C1348: MT | D1348: ATACADO | E1348: POWER PACKS | F1348: SPT 269 | G1348: 3.99 | H1348: 3.49 | I1348: =_xlfn.XLOOKUP(F1348,DeparaIMG!D:D,DeparaIMG!F:F,,0) -> SPT269.png
A1349: Outubro | B1349: CERV | C1349: MT | D1349: ATACADO | E1349: POWER PACKS | F1349: STE 269 | G1349: 4.29 | H1349: 3.49 | I1349: =_xlfn.XLOOKUP(F1349,DeparaIMG!D:D,DeparaIMG!F:F,,0) -> STE269.png
... A1449: Novembro | B1449: CERV | C1449: RO | D1449: ATACADO | E1449: POWER PACKS | F1449: SPT LN | G1449: 6.49 | H1449: 5.99 | I1449: =_xlfn.XLOOKUP(F1449,DeparaIMG!D:D,DeparaIMG!F:F,,0) -> SPTLN.png
...

Sheet CONFIG
A1: Chave | B1: Valor
A2: MesAtual | B2: Outubro
A3: AnoAtual | B3: 2026
A4: RegionalPadrao | B4: DF
A5: Logo | B5: logo.png
A6: Titulo | B6: Calendário 2.0
